Workbook

Sheet START HERE
A1: Reseller Inventory & Profit Tracker 2026
A2: For eBay - Poshmark - Mercari - Depop - Whatnot - Facebook Marketplace - Etsy sellers
A4: HOW TO USE
A5: 1 | B5: Settings: review platform fee rates (pre-filled approximations - verify against each platform's current fee page) and set your mileage rate, stale-item threshold and year start date.
A6: 2 | B6: Inventory: log every item you buy, one per row. SKU is auto-generated when you enter a purchase date (you can overwrite it with your own code). Set Status to Listed and add the Date Listed when it goes live.
A7: 3 | B7: Sales: when an item sells, enter the Date Sold, SKU, Platform, Sale Price and shipping details. Description, cost, fees, profit, ROI and days-to-sell are calculated for you. Remember to change the item's Status to Sold on the Inventory sheet.
A8: 4 | B8: Expenses: record business costs not tied to one item (supplies, subscriptions, storage, mileage). Enter miles in the Miles column and the deduction is calculated at your Settings rate.
A9: 5 | B9: Dashboard, Death Pile and Tax Summary update automatically. Nothing needs to be typed on those sheets.
A11: LEGEND
A12: BLUE text | B12: Cells you type into (inputs). Dropdowns are provided where a list is expected.
A13: BLACK text | B13: Formulas - do not overwrite. If you accidentally delete one, copy the cell above it and paste down.
A14: Grey 'helper' columns | B14: Support the Dashboard and Death Pile lookups. Leave them in place; you may hide them.
A16: SAMPLE DATA
A17: Delete before use | B17: Inventory, Sales and Expenses contain sample rows (Patagonia fleece, Pyrex, Nike etc.) so you can see how the tracker works. Select those rows and press Delete (clear contents) - do not delete whole rows, because SKUs are numbered by row position and formulas run down to row 503.
A18: Rows supported | B18: 500 inventory items, 500 sales and 500 expense lines per copy. Start a fresh copy of the file each year (change the Year Start Date in Settings).
A20: TIPS
A21: Sell-through rate | B21: Items sold / items sourced this year. Full-time flippers typically aim for 30%+ per quarter.
A22: Death Pile | B22: Any Listed item older than the stale threshold (default 60 days) is flagged. Reprice, bundle, or relist it.
A23: Fee accuracy | B23: Fees are estimates using the Settings table. Promoted listings, store subscriptions and international fees are not modelled - add them to Other Costs on the Sales row.
A24: Check the fee rates | B24: Platforms change their fees without much notice, and a wrong rate quietly distorts every profit and ROI figure in this workbook. The 'Rates last checked' column in Settings tells you which rows have been verified and which have not - the honest answer is that most say 'not re-verified'. Spend five minutes against each platform's current fee page before you trust the numbers, and update Settings; everything else recalculates.
A26: DISCLAIMER
A27: Not tax advice | B27: This workbook is a bookkeeping aid only. The Tax Summary is an estimate mapped loosely to US Schedule C categories and is not a substitute for advice from a qualified tax professional. Fee rates and the mileage rate are user-editable approximations - verify them for your situation.

Sheet Settings
A1: Settings
A2: Blue cells are yours to edit. All other sheets read from here.
A3: Platform | B3: Fee % | C3: Fixed Fee / Sale | D3: Payment Processing % | E3: Fee on Buyer Shipping? (Y/N) | F3: Notes - verify against the platform's current fee page | G3: Rates last checked | H3: Sources | I3: Categories | J3: Statuses | K3: Expense Categories
A4: eBay | B4: 0.136 | C4: 0.4 | D4: 0 | E4: Y | F4: Final value fee ~13.6% of total incl. shipping + $0.40 per order (most categories). | G4: not re-verified | H4: Thrift | I4: Clothing | J4: Sourced | K4: Supplies
A5: Poshmark | B5: 0.2 | C5: 0 | D5: 0 | E5: N | F5: 20% of sale price at/over the threshold below; flat fee under it. Buyer pays shipping. | G5: not re-verified | H5: Estate Sale | I5: Shoes | J5: Listed | K5: Shipping Supplies
A6: Mercari | B6: 0.1 | C6: 0 | D6: 0 | E6: Y | F6: Flat 10% on item + buyer-paid shipping. The separate 2.9% + $0.50 seller payment-processing fee was removed on 6 Jan 2025; buyers now pay a 3.6% Buyer Protection fee instead. | G6: 2026-09-10 | H6: Garage Sale | I6: Accessories | J6: Sold | K6: Mileage
A7: Depop | B7: 0 | C7: 0.45 | D7: 0.033 | E7: Y | F7: No US selling commission since 2024 - it moved to the buyer. 3.3% + $0.45 payment processing remains on the seller, charged on item + shipping + tax. Optional Boosted Listings cost 12% on top and are not modelled. | G7: 2026-09-11 | H7: Auction | I7: Electronics | J7: Returned | K7: Subscriptions
A8: Whatnot | B8: 0.08 | C8: 0.3 | D8: 0.029 | E8: N | F8: 8% commission + 2.9% + $0.30 processing. | G8: not re-verified | H8: Online | I8: Home | J8: Donated | K8: Storage
A9: FB Marketplace | B9: 0.1 | C9: 0 | D9: 0 | E9: Y | F9: 10% of the buyer's total on shipped orders (raised from 5% on 15 Apr 2024), minimum $0.80 per order - this table has no minimum-fee column, so sales under $8 are understated by a few cents. Local pickup sales have no selling fee; log those as Other with 0%. | G9: 2026-09-11 | H9: Wholesale | I9: Toys | K9: Fees
A10: Etsy | B10: 0.065 | C10: 0.45 | D10: 0.03 | E10: Y | F10: 6.5% transaction + 3% + $0.25 processing + $0.20 listing fee. | G10: not re-verified | H10: Other | I10: Books & Media | K10: Other
A11: Other | B11: 0.1 | C11: 0 | D11: 0 | E11: N | F11: Generic placeholder - edit for any other marketplace. | G11: not re-verified | I11: Collectibles
I12: Other
A13: General Setting | B13: Value | C13: Notes
A14: Currency Symbol | B14: $ | C14: Used in Dashboard labels. Number formats use $ - change via Format Cells if needed. | H14: Lists feed the dropdowns on other sheets. Edit names here (keep the Statuses list as-is; formulas depend on it).
A15: Year Start Date | B15: 46023 | C15: Dashboard months run 12 months from this date.
A16: Sales Tax Rate (optional) | B16: 0 | C16: Only if you collect tax yourself (e.g. local cash sales). Marketplaces remit tax for you.
A17: Mileage Rate (per mile) | B17: 0.7 | C17: IRS standard mileage rate - 2026 default of 70 cents entered; verify the current rate at irs.gov.
A18: Default Shipping Cost | B18: 9 | C18: Reference figure for quick estimates when pricing.
A19: Stale Item Threshold (days) | B19: 60 | C19: Listed items older than this are flagged on the Death Pile.
A20: Poshmark Flat-Fee Threshold | B20: 15 | C20: Sales below this price pay the flat fee instead of the % fee.
A21: Poshmark Flat Fee | B21: 2.95 | C21: Flat fee charged on sales below the threshold.

Sheet Inventory
A1: Inventory
A2: One row per item. Blue = type, black = formula. Clear (don't delete) the sample rows before use.
A3: SKU | B3: Date Purchased | C3: Source | D3: Brand | E3: Item Description | F3: Category | G3: Size | H3: Cost of Goods | I3: Extra Costs (cleaning/repair) | J3: Total Cost | K3: Status | L3: Date Listed | M3: List Price | N3: Platform Listed | O3: Days in Inventory | P3: Days Listed | Q3: Stale? | R3: Stale # (helper)
A4: =IF(B4="","","SKU-"&TEXT(ROW()-3,"0000")) -> SKU-0001 | B4: 46034 | C4: Thrift | D4: Patagonia | E4: Men's Better Sweater Fleece Full-Zip, Navy | F4: Clothing | G4: L | H4: 12.99 | I4: 0 | J4: =IF(B4="","",N(H4)+N(I4)) -> 12.99 | K4: Sold | L4: 46037 | M4: 79 | N4: eBay | O4: =IF(OR(B4="",K4="Sold",K4="Donated"),"",TODAY()-B4) | P4: =IF(OR(L4="",K4="Sold",K4="Donated"),"",TODAY()-L4) | Q4: =IF(AND(K4="Listed",P4<>"",N(P4)>Settings!$B$19),"STALE","") | R4: =IF(Q4="STALE",COUNTIF($Q$4:Q4,"STALE"),"")
A5: =IF(B5="","","SKU-"&TEXT(ROW()-3,"0000")) -> SKU-0002 | B5: 46042 | C5: Estate Sale | D5: Pyrex | E5: Vintage Butterfly Gold Mixing Bowl Set (3 pc) | F5: Home | H5: 18 | I5: 2.5 | J5: =IF(B5="","",N(H5)+N(I5)) -> 20.5 | K5: Sold | L5: 46044 | M5: 65 | N5: Mercari | O5: =IF(OR(B5="",K5="Sold",K5="Donated"),"",TODAY()-B5) | P5: =IF(OR(L5="",K5="Sold",K5="Donated"),"",TODAY()-L5) | Q5: =IF(AND(K5="Listed",P5<>"",N(P5)>Settings!$B$19),"STALE","") | R5: =IF(Q5="STALE",COUNTIF($Q$4:Q5,"STALE"),"")
A6: =IF(B6="","","SKU-"&TEXT(ROW()-3,"0000")) -> SKU-0003 | B6: 46056 | C6: Thrift | D6: Nike | E6: Air Max 90 Sneakers, White/Grey | F6: Shoes | G6: 10 | H6: 22 | I6: 4 | J6: =IF(B6="","",N(H6)+N(I6)) -> 26 | K6: Sold | L6: 46058 | M6: 68 | N6: Poshmark | O6: =IF(OR(B6="",K6="Sold",K6="Donated"),"",TODAY()-B6) | P6: =IF(OR(L6="",K6="Sold",K6="Donated"),"",TODAY()-L6) | Q6: =IF(AND(K6="Listed",P6<>"",N(P6)>Settings!$B$19),"STALE","") | R6: =IF(Q6="STALE",COUNTIF($Q$4:Q6,"STALE"),"")
A7: =IF(B7="","","SKU-"&TEXT(ROW()-3,"0000")) -> SKU-0004 | B7: 46067 | C7: Garage Sale | D7: Gap Kids | E7: Denim Trucker Jacket, Medium Wash | F7: Clothing | G7: M (8) | H7: 3 | I7: 0 | J7: =IF(B7="","",N(H7)+N(I7)) -> 3 | K7: Sold | L7: 46069 | M7: 14 | N7: Poshmark | O7: =IF(OR(B7="",K7="Sold",K7="Donated"),"",TODAY()-B7) | P7: =IF(OR(L7="",K7="Sold",K7="Donated"),"",TODAY()-L7) | Q7: =IF(AND(K7="Listed",P7<>"",N(P7)>Settings!$B$19),"STALE","") | R7: =IF(Q7="STALE",COUNTIF($Q$4:Q7,"STALE"),"")
A8: =IF(B8="","","SKU-"&TEXT(ROW()-3,"0000")) -> SKU-0005 | B8: 46083 | C8: Online | D8: LEGO | E8: Creator Expert 10265 Ford Mustang (sealed) | F8: Toys | H8: 45 | I8: 0 | J8: =IF(B8="","",N(H8)+N(I8)) -> 45 | K8: Sold | L8: 46085 | M8: 95 | N8: Whatnot | O8: =IF(OR(B8="",K8="Sold",K8="Donated"),"",TODAY()-B8) | P8: =IF(OR(L8="",K8="Sold",K8="Donated"),"",TODAY()-L8) | Q8: =IF(AND(K8="Listed",P8<>"",N(P8)>Settings!$B$19),"STALE","") | R8: =IF(Q8="STALE",COUNTIF($Q$4:Q8,"STALE"),"")
A9: =IF(B9="","","SKU-"&TEXT(ROW()-3,"0000")) -> SKU-0006 | B9: 46099 | C9: Thrift | D9: Carhartt | E9: Detroit Jacket, Duck Canvas, Brown | F9: Clothing | G9: XL | H9: 24.99 | I9: 6 | J9: =IF(B9="","",N(H9)+N(I9)) -> 30.99 | K9: Listed | L9: 46101 | M9: 145 | N9: eBay | O9: =IF(OR(B9="",K9="Sold",K9="Donated"),"",TODAY()-B9) -> 188 | P9: =IF(OR(L9="",K9="Sold",K9="Donated"),"",TODAY()-L9) -> 186 | Q9: =IF(AND(K9="Listed",P9<>"",N(P9)>Settings!$B$19),"STALE","") -> STALE | R9: =IF(Q9="STALE",COUNTIF($Q$4:Q9,"STALE"),"") -> 1
A10: =IF(B10="","","SKU-"&TEXT(ROW()-3,"0000")) -> SKU-0007 | B10: 46178 | C10: Auction | D10: Sony | E10: Walkman WM-F41 Cassette Player (tested) | F10: Electronics | H10: 30 | I10: 0 | J10: =IF(B10="","",N(H10)+N(I10)) -> 30 | K10: Listed | L10: 46254 | M10: 89 | N10: eBay | O10: =IF(OR(B10="",K10="Sold",K10="Donated"),"",TODAY()-B10) -> 109 | P10: =IF(OR(L10="",K10="Sold",K10="Donated"),"",TODAY()-L10) -> 33 | Q10: =IF(AND(K10="Listed",P10<>"",N(P10)>Settings!$B$19),"STALE","") | R10: =IF(Q10="STALE",COUNTIF($Q$4:Q10,"STALE"),"")
A11: =IF(B11="","","SKU-"&TEXT(ROW()-3,"0000")) -> SKU-0008 | B11: 46262 | C11: Wholesale | D11: Lululemon | E11: Align High-Rise Leggings 25", Black | F11: Clothing | G11: 6 | H11: 20 | I11: 0 | J11: =IF(B11="","",N(H11)+N(I11)) -> 20 | K11: Sourced | O11: =IF(OR(B11="",K11="Sold",K11="Donated"),"",TODAY()-B11) -> 25 | P11: =IF(OR(L11="",K11="Sold",K11="Donated"),"",TODAY()-L11) | Q11: =IF(AND(K11="Listed",P11<>"",N(P11)>Settings!$B$19),"STALE","") | R11: =IF(Q11="STALE",COUNTIF($Q$4:Q11,"STALE"),"")
A12: =IF(B12="","","SKU-"&TEXT(ROW()-3,"0000")) | J12: =IF(B12="","",N(H12)+N(I12)) | O12: =IF(OR(B12="",K12="Sold",K12="Donated"),"",TODAY()-B12) | P12: =IF(OR(L12="",K12="Sold",K12="Donated"),"",TODAY()-L12) | Q12: =IF(AND(K12="Listed",P12<>"",N(P12)>Settings!$B$19),"STALE","") | R12: =IF(Q12="STALE",COUNTIF($Q$4:Q12,"STALE"),"")
A13: =IF(B13="","","SKU-"&TEXT(ROW()-3,"0000")) | J13: =IF(B13="","",N(H13)+N(I13)) | O13: =IF(OR(B13="",K13="Sold",K13="Donated"),"",TODAY()-B13) | P13: =IF(OR(L13="",K13="Sold",K13="Donated"),"",TODAY()-L13) | Q13: =IF(AND(K13="Listed",P13<>"",N(P13)>Settings!$B$19),"STALE","") | R13: =IF(Q13="STALE",COUNTIF($Q$4:Q13,"STALE"),"")
A14: =IF(B14="","","SKU-"&TEXT(ROW()-3,"0000")) | J14: =IF(B14="","",N(H14)+N(I14)) | O14: =IF(OR(B14="",K14="Sold",K14="Donated"),"",TODAY()-B14) | P14: =IF(OR(L14="",K14="Sold",K14="Donated"),"",TODAY()-L14) | Q14: =IF(AND(K14="Listed",P14<>"",N(P14)>Settings!$B$19),"STALE","") | R14: =IF(Q14="STALE",COUNTIF($Q$4:Q14,"STALE"),"")
A15: =IF(B15="","","SKU-"&TEXT(ROW()-3,"0000")) | J15: =IF(B15="","",N(H15)+N(I15)) | O15: =IF(OR(B15="",K15="Sold",K15="Donated"),"",TODAY()-B15) | P15: =IF(OR(L15="",K15="Sold",K15="Donated"),"",TODAY()-L15) | Q15: =IF(AND(K15="Listed",P15<>"",N(P15)>Settings!$B$19),"STALE","") | R15: =IF(Q15="STALE",COUNTIF($Q$4:Q15,"STALE"),"")
A16: =IF(B16="","","SKU-"&TEXT(ROW()-3,"0000")) | J16: =IF(B16="","",N(H16)+N(I16)) | O16: =IF(OR(B16="",K16="Sold",K16="Donated"),"",TODAY()-B16) | P16: =IF(OR(L16="",K16="Sold",K16="Donated"),"",TODAY()-L16) | Q16: =IF(AND(K16="Listed",P16<>"",N(P16)>Settings!$B$19),"STALE","") | R16: =IF(Q16="STALE",COUNTIF($Q$4:Q16,"STALE"),"")
A17: =IF(B17="","","SKU-"&TEXT(ROW()-3,"0000")) | J17: =IF(B17="","",N(H17)+N(I17)) | O17: =IF(OR(B17="",K17="Sold",K17="Donated"),"",TODAY()-B17) | P17: =IF(OR(L17="",K17="Sold",K17="Donated"),"",TODAY()-L17) | Q17: =IF(AND(K17="Listed",P17<>"",N(P17)>Settings!$B$19),"STALE","") | R17: =IF(Q17="STALE",COUNTIF($Q$4:Q17,"STALE"),"")
A18: =IF(B18="","","SKU-"&TEXT(ROW()-3,"0000")) | J18: =IF(B18="","",N(H18)+N(I18)) | O18: =IF(OR(B18="",K18="Sold",K18="Donated"),"",TODAY()-B18) | P18: =IF(OR(L18="",K18="Sold",K18="Donated"),"",TODAY()-L18) | Q18: =IF(AND(K18="Listed",P18<>"",N(P18)>Settings!$B$19),"STALE","") | R18: =IF(Q18="STALE",COUNTIF($Q$4:Q18,"STALE"),"")
A19: =IF(B19="","","SKU-"&TEXT(ROW()-3,"0000")) | J19: =IF(B19="","",N(H19)+N(I19)) | O19: =IF(OR(B19="",K19="Sold",K19="Donated"),"",TODAY()-B19) | P19: =IF(OR(L19="",K19="Sold",K19="Donated"),"",TODAY()-L19) | Q19: =IF(AND(K19="Listed",P19<>"",N(P19)>Settings!$B$19),"STALE","") | R19: =IF(Q19="STALE",COUNTIF($Q$4:Q19,"STALE"),"")
A20: =IF(B20="","","SKU-"&TEXT(ROW()-3,"0000")) | J20: =IF(B20="","",N(H20)+N(I20)) | O20: =IF(OR(B20="",K20="Sold",K20="Donated"),"",TODAY()-B20) | P20: =IF(OR(L20="",K20="Sold",K20="Donated"),"",TODAY()-L20) | Q20: =IF(AND(K20="Listed",P20<>"",N(P20)>Settings!$B$19),"STALE","") | R20: =IF(Q20="STALE",COUNTIF($Q$4:Q20,"STALE"),"")
A21: =IF(B21="","","SKU-"&TEXT(ROW()-3,"0000")) | J21: =IF(B21="","",N(H21)+N(I21)) | O21: =IF(OR(B21="",K21="Sold",K21="Donated"),"",TODAY()-B21) | P21: =IF(OR(L21="",K21="Sold",K21="Donated"),"",TODAY()-L21) | Q21: =IF(AND(K21="Listed",P21<>"",N(P21)>Settings!$B$19),"STALE","") | R21: =IF(Q21="STALE",COUNTIF($Q$4:Q21,"STALE"),"")
A22: =IF(B22="","","SKU-"&TEXT(ROW()-3,"0000")) | J22: =IF(B22="","",N(H22)+N(I22)) | O22: =IF(OR(B22="",K22="Sold",K22="Donated"),"",TODAY()-B22) | P22: =IF(OR(L22="",K22="Sold",K22="Donated"),"",TODAY()-L22) | Q22: =IF(AND(K22="Listed",P22<>"",N(P22)>Settings!$B$19),"STALE","") | R22: =IF(Q22="STALE",COUNTIF($Q$4:Q22,"STALE"),"")
A23: =IF(B23="","","SKU-"&TEXT(ROW()-3,"0000")) | J23: =IF(B23="","",N(H23)+N(I23)) | O23: =IF(OR(B23="",K23="Sold",K23="Donated"),"",TODAY()-B23) | P23: =IF(OR(L23="",K23="Sold",K23="Donated"),"",TODAY()-L23) | Q23: =IF(AND(K23="Listed",P23<>"",N(P23)>Settings!$B$19),"STALE","") | R23: =IF(Q23="STALE",COUNTIF($Q$4:Q23,"STALE"),"")
... A503: =IF(B503="","","SKU-"&TEXT(ROW()-3,"0000")) | J503: =IF(B503="","",N(H503)+N(I503)) | O503: =IF(OR(B503="",K503="Sold",K503="Donated"),"",TODAY()-B503) | P503: =IF(OR(L503="",K503="Sold",K503="Donated"),"",TODAY()-L503) | Q503: =IF(AND(K503="Listed",P503<>"",N(P503)>Settings!$B$19),"STALE","") | R503: =IF(Q503="STALE",COUNTIF($Q$4:Q503,"STALE"),"")

Sheet Sales
A1: Sales
A2: Enter Date Sold, SKU, Platform, Sale Price and shipping. Everything else is calculated. Fees follow the Settings table.
A3: Date Sold | B3: SKU | C3: Item Description | D3: Platform | E3: Sale Price | F3: Shipping Charged to Buyer | G3: Shipping Cost Paid | H3: Platform Fees (est.) | I3: Sales Tax Collected by Platform (info) | J3: Other Costs | K3: Item Total Cost | L3: Net Profit | M3: ROI % | N3: Days to Sell | O3: Category (helper) | P3: Source (helper)
A4: 46050 | B4: SKU-0001 | C4: =IF($B4="","",IFERROR(INDEX(Inventory!$E$4:$E$503,MATCH($B4,Inventory!$A$4:$A$503,0)),"SKU not found")) -> Men's Better Sweater Fleece Full-Zip, Navy | D4: eBay | E4: 79 | F4: 0 | G4: 9.85 | H4: =IF(OR(B4="",D4="",E4=""),"",IFERROR(IF(AND(D4="Poshmark",E4<Settings!$B$20),Settings!$B$21,(E4+IF(INDEX(Settings!$E$4:$E$11,MATCH($D4,Settings!$A$4:$A$11,0))="Y",N(F4),0))*(INDEX(Settings!$B$4:$B$11,MATCH($D4,Settings!$A$4:$A$11,0))+INDEX(Settings!$D$4:$D$11,MATCH($D4,Settings!$A$4:$A$11,0)))+INDEX(Settings!$C$4:$C$11,MATCH($D4,Settings!$A$4:$A$11,0))),0)) -> 11.144 | I4: 5.53 | J4: 0 | K4: =IF($B4="","",IFERROR(INDEX(Inventory!$J$4:$J$503,MATCH($B4,Inventory!$A$4:$A$503,0)),0)) -> 12.99 | L4: =IF(OR(B4="",E4=""),"",E4+N(F4)-N(G4)-N(H4)-N(J4)-N(K4)) -> 45.016 | M4: =IF(OR(L4="",N(K4)=0),"",L4/K4) -> 3.4654349 | N4: =IF(OR(A4="",B4=""),"",IFERROR(A4-INDEX(Inventory!$B$4:$B$503,MATCH($B4,Inventory!$A$4:$A$503,0)),"")) -> 16 | O4: =IF($B4="","",IFERROR(INDEX(Inventory!$F$4:$F$503,MATCH($B4,Inventory!$A$4:$A$503,0)),"")) -> Clothing | P4: =IF($B4="","",IFERROR(INDEX(Inventory!$C$4:$C$503,MATCH($B4,Inventory!$A$4:$A$503,0)),"")) -> Thrift
A5: 46063 | B5: SKU-0002 | C5: =IF($B5="","",IFERROR(INDEX(Inventory!$E$4:$E$503,MATCH($B5,Inventory!$A$4:$A$503,0)),"SKU not found")) -> Vintage Butterfly Gold Mixing Bowl Set (3 pc) | D5: Mercari | E5: 65 | F5: 12.99 | G5: 14.2 | H5: =IF(OR(B5="",D5="",E5=""),"",IFERROR(IF(AND(D5="Poshmark",E5<Settings!$B$20),Settings!$B$21,(E5+IF(INDEX(Settings!$E$4:$E$11,MATCH($D5,Settings!$A$4:$A$11,0))="Y",N(F5),0))*(INDEX(Settings!$B$4:$B$11,MATCH($D5,Settings!$A$4:$A$11,0))+INDEX(Settings!$D$4:$D$11,MATCH($D5,Settings!$A$4:$A$11,0)))+INDEX(Settings!$C$4:$C$11,MATCH($D5,Settings!$A$4:$A$11,0))),0)) -> 7.799 | I5: 5.85 | J5: 1.5 | K5: =IF($B5="","",IFERROR(INDEX(Inventory!$J$4:$J$503,MATCH($B5,Inventory!$A$4:$A$503,0)),0)) -> 20.5 | L5: =IF(OR(B5="",E5=""),"",E5+N(F5)-N(G5)-N(H5)-N(J5)-N(K5)) -> 33.991 | M5: =IF(OR(L5="",N(K5)=0),"",L5/K5) -> 1.6580976 | N5: =IF(OR(A5="",B5=""),"",IFERROR(A5-INDEX(Inventory!$B$4:$B$503,MATCH($B5,Inventory!$A$4:$A$503,0)),"")) -> 21 | O5: =IF($B5="","",IFERROR(INDEX(Inventory!$F$4:$F$503,MATCH($B5,Inventory!$A$4:$A$503,0)),"")) -> Home | P5: =IF($B5="","",IFERROR(INDEX(Inventory!$C$4:$C$503,MATCH($B5,Inventory!$A$4:$A$503,0)),"")) -> Estate Sale
A6: 46074 | B6: SKU-0003 | C6: =IF($B6="","",IFERROR(INDEX(Inventory!$E$4:$E$503,MATCH($B6,Inventory!$A$4:$A$503,0)),"SKU not found")) -> Air Max 90 Sneakers, White/Grey | D6: Poshmark | E6: 68 | F6: 0 | G6: 0 | H6: =IF(OR(B6="",D6="",E6=""),"",IFERROR(IF(AND(D6="Poshmark",E6<Settings!$B$20),Settings!$B$21,(E6+IF(INDEX(Settings!$E$4:$E$11,MATCH($D6,Settings!$A$4:$A$11,0))="Y",N(F6),0))*(INDEX(Settings!$B$4:$B$11,MATCH($D6,Settings!$A$4:$A$11,0))+INDEX(Settings!$D$4:$D$11,MATCH($D6,Settings!$A$4:$A$11,0)))+INDEX(Settings!$C$4:$C$11,MATCH($D6,Settings!$A$4:$A$11,0))),0)) -> 13.6 | I6: 0 | J6: 0 | K6: =IF($B6="","",IFERROR(INDEX(Inventory!$J$4:$J$503,MATCH($B6,Inventory!$A$4:$A$503,0)),0)) -> 26 | L6: =IF(OR(B6="",E6=""),"",E6+N(F6)-N(G6)-N(H6)-N(J6)-N(K6)) -> 28.4 | M6: =IF(OR(L6="",N(K6)=0),"",L6/K6) -> 1.0923077 | N6: =IF(OR(A6="",B6=""),"",IFERROR(A6-INDEX(Inventory!$B$4:$B$503,MATCH($B6,Inventory!$A$4:$A$503,0)),"")) -> 18 | O6: =IF($B6="","",IFERROR(INDEX(Inventory!$F$4:$F$503,MATCH($B6,Inventory!$A$4:$A$503,0)),"")) -> Shoes | P6: =IF($B6="","",IFERROR(INDEX(Inventory!$C$4:$C$503,MATCH($B6,Inventory!$A$4:$A$503,0)),"")) -> Thrift
A7: 46082 | B7: SKU-0004 | C7: =IF($B7="","",IFERROR(INDEX(Inventory!$E$4:$E$503,MATCH($B7,Inventory!$A$4:$A$503,0)),"SKU not found")) -> Denim Trucker Jacket, Medium Wash | D7: Poshmark | E7: 14 | F7: 0 | G7: 0 | H7: =IF(OR(B7="",D7="",E7=""),"",IFERROR(IF(AND(D7="Poshmark",E7<Settings!$B$20),Settings!$B$21,(E7+IF(INDEX(Settings!$E$4:$E$11,MATCH($D7,Settings!$A$4:$A$11,0))="Y",N(F7),0))*(INDEX(Settings!$B$4:$B$11,MATCH($D7,Settings!$A$4:$A$11,0))+INDEX(Settings!$D$4:$D$11,MATCH($D7,Settings!$A$4:$A$11,0)))+INDEX(Settings!$C$4:$C$11,MATCH($D7,Settings!$A$4:$A$11,0))),0)) -> 2.95 | I7: 0 | J7: 0 | K7: =IF($B7="","",IFERROR(INDEX(Inventory!$J$4:$J$503,MATCH($B7,Inventory!$A$4:$A$503,0)),0)) -> 3 | L7: =IF(OR(B7="",E7=""),"",E7+N(F7)-N(G7)-N(H7)-N(J7)-N(K7)) -> 8.05 | M7: =IF(OR(L7="",N(K7)=0),"",L7/K7) -> 2.6833333 | N7: =IF(OR(A7="",B7=""),"",IFERROR(A7-INDEX(Inventory!$B$4:$B$503,MATCH($B7,Inventory!$A$4:$A$503,0)),"")) -> 15 | O7: =IF($B7="","",IFERROR(INDEX(Inventory!$F$4:$F$503,MATCH($B7,Inventory!$A$4:$A$503,0)),"")) -> Clothing | P7: =IF($B7="","",IFERROR(INDEX(Inventory!$C$4:$C$503,MATCH($B7,Inventory!$A$4:$A$503,0)),"")) -> Garage Sale
A8: 46137 | B8: SKU-0005 | C8: =IF($B8="","",IFERROR(INDEX(Inventory!$E$4:$E$503,MATCH($B8,Inventory!$A$4:$A$503,0)),"SKU not found")) -> Creator Expert 10265 Ford Mustang (sealed) | D8: Whatnot | E8: 95 | F8: 8 | G8: 11.4 | H8: =IF(OR(B8="",D8="",E8=""),"",IFERROR(IF(AND(D8="Poshmark",E8<Settings!$B$20),Settings!$B$21,(E8+IF(INDEX(Settings!$E$4:$E$11,MATCH($D8,Settings!$A$4:$A$11,0))="Y",N(F8),0))*(INDEX(Settings!$B$4:$B$11,MATCH($D8,Settings!$A$4:$A$11,0))+INDEX(Settings!$D$4:$D$11,MATCH($D8,Settings!$A$4:$A$11,0)))+INDEX(Settings!$C$4:$C$11,MATCH($D8,Settings!$A$4:$A$11,0))),0)) -> 10.655 | I8: 7.6 | J8: 0 | K8: =IF($B8="","",IFERROR(INDEX(Inventory!$J$4:$J$503,MATCH($B8,Inventory!$A$4:$A$503,0)),0)) -> 45 | L8: =IF(OR(B8="",E8=""),"",E8+N(F8)-N(G8)-N(H8)-N(J8)-N(K8)) -> 35.945 | M8: =IF(OR(L8="",N(K8)=0),"",L8/K8) -> 0.79877778 | N8: =IF(OR(A8="",B8=""),"",IFERROR(A8-INDEX(Inventory!$B$4:$B$503,MATCH($B8,Inventory!$A$4:$A$503,0)),"")) -> 54 | O8: =IF($B8="","",IFERROR(INDEX(Inventory!$F$4:$F$503,MATCH($B8,Inventory!$A$4:$A$503,0)),"")) -> Toys | P8: =IF($B8="","",IFERROR(INDEX(Inventory!$C$4:$C$503,MATCH($B8,Inventory!$A$4:$A$503,0)),"")) -> Online
C9: =IF($B9="","",IFERROR(INDEX(Inventory!$E$4:$E$503,MATCH($B9,Inventory!$A$4:$A$503,0)),"SKU not found")) | H9: =IF(OR(B9="",D9="",E9=""),"",IFERROR(IF(AND(D9="Poshmark",E9<Settings!$B$20),Settings!$B$21,(E9+IF(INDEX(Settings!$E$4:$E$11,MATCH($D9,Settings!$A$4:$A$11,0))="Y",N(F9),0))*(INDEX(Settings!$B$4:$B$11,MATCH($D9,Settings!$A$4:$A$11,0))+INDEX(Settings!$D$4:$D$11,MATCH($D9,Settings!$A$4:$A$11,0)))+INDEX(Settings!$C$4:$C$11,MATCH($D9,Settings!$A$4:$A$11,0))),0)) | K9: =IF($B9="","",IFERROR(INDEX(Inventory!$J$4:$J$503,MATCH($B9,Inventory!$A$4:$A$503,0)),0)) | L9: =IF(OR(B9="",E9=""),"",E9+N(F9)-N(G9)-N(H9)-N(J9)-N(K9)) | M9: =IF(OR(L9="",N(K9)=0),"",L9/K9) | N9: =IF(OR(A9="",B9=""),"",IFERROR(A9-INDEX(Inventory!$B$4:$B$503,MATCH($B9,Inventory!$A$4:$A$503,0)),"")) | O9: =IF($B9="","",IFERROR(INDEX(Inventory!$F$4:$F$503,MATCH($B9,Inventory!$A$4:$A$503,0)),"")) | P9: =IF($B9="","",IFERROR(INDEX(Inventory!$C$4:$C$503,MATCH($B9,Inventory!$A$4:$A$503,0)),""))
C10: =IF($B10="","",IFERROR(INDEX(Inventory!$E$4:$E$503,MATCH($B10,Inventory!$A$4:$A$503,0)),"SKU not found")) | H10: =IF(OR(B10="",D10="",E10=""),"",IFERROR(IF(AND(D10="Poshmark",E10<Settings!$B$20),Settings!$B$21,(E10+IF(INDEX(Settings!$E$4:$E$11,MATCH($D10,Settings!$A$4:$A$11,0))="Y",N(F10),0))*(INDEX(Settings!$B$4:$B$11,MATCH($D10,Settings!$A$4:$A$11,0))+INDEX(Settings!$D$4:$D$11,MATCH($D10,Settings!$A$4:$A$11,0)))+INDEX(Settings!$C$4:$C$11,MATCH($D10,Settings!$A$4:$A$11,0))),0)) | K10: =IF($B10="","",IFERROR(INDEX(Inventory!$J$4:$J$503,MATCH($B10,Inventory!$A$4:$A$503,0)),0)) | L10: =IF(OR(B10="",E10=""),"",E10+N(F10)-N(G10)-N(H10)-N(J10)-N(K10)) | M10: =IF(OR(L10="",N(K10)=0),"",L10/K10) | N10: =IF(OR(A10="",B10=""),"",IFERROR(A10-INDEX(Inventory!$B$4:$B$503,MATCH($B10,Inventory!$A$4:$A$503,0)),"")) | O10: =IF($B10="","",IFERROR(INDEX(Inventory!$F$4:$F$503,MATCH($B10,Inventory!$A$4:$A$503,0)),"")) | P10: =IF($B10="","",IFERROR(INDEX(Inventory!$C$4:$C$503,MATCH($B10,Inventory!$A$4:$A$503,0)),""))
C11: =IF($B11="","",IFERROR(INDEX(Inventory!$E$4:$E$503,MATCH($B11,Inventory!$A$4:$A$503,0)),"SKU not found")) | H11: =IF(OR(B11="",D11="",E11=""),"",IFERROR(IF(AND(D11="Poshmark",E11<Settings!$B$20),Settings!$B$21,(E11+IF(INDEX(Settings!$E$4:$E$11,MATCH($D11,Settings!$A$4:$A$11,0))="Y",N(F11),0))*(INDEX(Settings!$B$4:$B$11,MATCH($D11,Settings!$A$4:$A$11,0))+INDEX(Settings!$D$4:$D$11,MATCH($D11,Settings!$A$4:$A$11,0)))+INDEX(Settings!$C$4:$C$11,MATCH($D11,Settings!$A$4:$A$11,0))),0)) | K11: =IF($B11="","",IFERROR(INDEX(Inventory!$J$4:$J$503,MATCH($B11,Inventory!$A$4:$A$503,0)),0)) | L11: =IF(OR(B11="",E11=""),"",E11+N(F11)-N(G11)-N(H11)-N(J11)-N(K11)) | M11: =IF(OR(L11="",N(K11)=0),"",L11/K11) | N11: =IF(OR(A11="",B11=""),"",IFERROR(A11-INDEX(Inventory!$B$4:$B$503,MATCH($B11,Inventory!$A$4:$A$503,0)),"")) | O11: =IF($B11="","",IFERROR(INDEX(Inventory!$F$4:$F$503,MATCH($B11,Inventory!$A$4:$A$503,0)),"")) | P11: =IF($B11="","",IFERROR(INDEX(Inventory!$C$4:$C$503,MATCH($B11,Inventory!$A$4:$A$503,0)),""))
C12: =IF($B12="","",IFERROR(INDEX(Inventory!$E$4:$E$503,MATCH($B12,Inventory!$A$4:$A$503,0)),"SKU not found")) | H12: =IF(OR(B12="",D12="",E12=""),"",IFERROR(IF(AND(D12="Poshmark",E12<Settings!$B$20),Settings!$B$21,(E12+IF(INDEX(Settings!$E$4:$E$11,MATCH($D12,Settings!$A$4:$A$11,0))="Y",N(F12),0))*(INDEX(Settings!$B$4:$B$11,MATCH($D12,Settings!$A$4:$A$11,0))+INDEX(Settings!$D$4:$D$11,MATCH($D12,Settings!$A$4:$A$11,0)))+INDEX(Settings!$C$4:$C$11,MATCH($D12,Settings!$A$4:$A$11,0))),0)) | K12: =IF($B12="","",IFERROR(INDEX(Inventory!$J$4:$J$503,MATCH($B12,Inventory!$A$4:$A$503,0)),0)) | L12: =IF(OR(B12="",E12=""),"",E12+N(F12)-N(G12)-N(H12)-N(J12)-N(K12)) | M12: =IF(OR(L12="",N(K12)=0),"",L12/K12) | N12: =IF(OR(A12="",B12=""),"",IFERROR(A12-INDEX(Inventory!$B$4:$B$503,MATCH($B12,Inventory!$A$4:$A$503,0)),"")) | O12: =IF($B12="","",IFERROR(INDEX(Inventory!$F$4:$F$503,MATCH($B12,Inventory!$A$4:$A$503,0)),"")) | P12: =IF($B12="","",IFERROR(INDEX(Inventory!$C$4:$C$503,MATCH($B12,Inventory!$A$4:$A$503,0)),""))
C13: =IF($B13="","",IFERROR(INDEX(Inventory!$E$4:$E$503,MATCH($B13,Inventory!$A$4:$A$503,0)),"SKU not found")) | H13: =IF(OR(B13="",D13="",E13=""),"",IFERROR(IF(AND(D13="Poshmark",E13<Settings!$B$20),Settings!$B$21,(E13+IF(INDEX(Settings!$E$4:$E$11,MATCH($D13,Settings!$A$4:$A$11,0))="Y",N(F13),0))*(INDEX(Settings!$B$4:$B$11,MATCH($D13,Settings!$A$4:$A$11,0))+INDEX(Settings!$D$4:$D$11,MATCH($D13,Settings!$A$4:$A$11,0)))+INDEX(Settings!$C$4:$C$11,MATCH($D13,Settings!$A$4:$A$11,0))),0)) | K13: =IF($B13="","",IFERROR(INDEX(Inventory!$J$4:$J$503,MATCH($B13,Inventory!$A$4:$A$503,0)),0)) | L13: =IF(OR(B13="",E13=""),"",E13+N(F13)-N(G13)-N(H13)-N(J13)-N(K13)) | M13: =IF(OR(L13="",N(K13)=0),"",L13/K13) | N13: =IF(OR(A13="",B13=""),"",IFERROR(A13-INDEX(Inventory!$B$4:$B$503,MATCH($B13,Inventory!$A$4:$A$503,0)),"")) | O13: =IF($B13="","",IFERROR(INDEX(Inventory!$F$4:$F$503,MATCH($B13,Inventory!$A$4:$A$503,0)),"")) | P13: =IF($B13="","",IFERROR(INDEX(Inventory!$C$4:$C$503,MATCH($B13,Inventory!$A$4:$A$503,0)),""))
C14: =IF($B14="","",IFERROR(INDEX(Inventory!$E$4:$E$503,MATCH($B14,Inventory!$A$4:$A$503,0)),"SKU not found")) | H14: =IF(OR(B14="",D14="",E14=""),"",IFERROR(IF(AND(D14="Poshmark",E14<Settings!$B$20),Settings!$B$21,(E14+IF(INDEX(Settings!$E$4:$E$11,MATCH($D14,Settings!$A$4:$A$11,0))="Y",N(F14),0))*(INDEX(Settings!$B$4:$B$11,MATCH($D14,Settings!$A$4:$A$11,0))+INDEX(Settings!$D$4:$D$11,MATCH($D14,Settings!$A$4:$A$11,0)))+INDEX(Settings!$C$4:$C$11,MATCH($D14,Settings!$A$4:$A$11,0))),0)) | K14: =IF($B14="","",IFERROR(INDEX(Inventory!$J$4:$J$503,MATCH($B14,Inventory!$A$4:$A$503,0)),0)) | L14: =IF(OR(B14="",E14=""),"",E14+N(F14)-N(G14)-N(H14)-N(J14)-N(K14)) | M14: =IF(OR(L14="",N(K14)=0),"",L14/K14) | N14: =IF(OR(A14="",B14=""),"",IFERROR(A14-INDEX(Inventory!$B$4:$B$503,MATCH($B14,Inventory!$A$4:$A$503,0)),"")) | O14: =IF($B14="","",IFERROR(INDEX(Inventory!$F$4:$F$503,MATCH($B14,Inventory!$A$4:$A$503,0)),"")) | P14: =IF($B14="","",IFERROR(INDEX(Inventory!$C$4:$C$503,MATCH($B14,Inventory!$A$4:$A$503,0)),""))
C15: =IF($B15="","",IFERROR(INDEX(Inventory!$E$4:$E$503,MATCH($B15,Inventory!$A$4:$A$503,0)),"SKU not found")) | H15: =IF(OR(B15="",D15="",E15=""),"",IFERROR(IF(AND(D15="Poshmark",E15<Settings!$B$20),Settings!$B$21,(E15+IF(INDEX(Settings!$E$4:$E$11,MATCH($D15,Settings!$A$4:$A$11,0))="Y",N(F15),0))*(INDEX(Settings!$B$4:$B$11,MATCH($D15,Settings!$A$4:$A$11,0))+INDEX(Settings!$D$4:$D$11,MATCH($D15,Settings!$A$4:$A$11,0)))+INDEX(Settings!$C$4:$C$11,MATCH($D15,Settings!$A$4:$A$11,0))),0)) | K15: =IF($B15="","",IFERROR(INDEX(Inventory!$J$4:$J$503,MATCH($B15,Inventory!$A$4:$A$503,0)),0)) | L15: =IF(OR(B15="",E15=""),"",E15+N(F15)-N(G15)-N(H15)-N(J15)-N(K15)) | M15: =IF(OR(L15="",N(K15)=0),"",L15/K15) | N15: =IF(OR(A15="",B15=""),"",IFERROR(A15-INDEX(Inventory!$B$4:$B$503,MATCH($B15,Inventory!$A$4:$A$503,0)),"")) | O15: =IF($B15="","",IFERROR(INDEX(Inventory!$F$4:$F$503,MATCH($B15,Inventory!$A$4:$A$503,0)),"")) | P15: =IF($B15="","",IFERROR(INDEX(Inventory!$C$4:$C$503,MATCH($B15,Inventory!$A$4:$A$503,0)),""))
C16: =IF($B16="","",IFERROR(INDEX(Inventory!$E$4:$E$503,MATCH($B16,Inventory!$A$4:$A$503,0)),"SKU not found")) | H16: =IF(OR(B16="",D16="",E16=""),"",IFERROR(IF(AND(D16="Poshmark",E16<Settings!$B$20),Settings!$B$21,(E16+IF(INDEX(Settings!$E$4:$E$11,MATCH($D16,Settings!$A$4:$A$11,0))="Y",N(F16),0))*(INDEX(Settings!$B$4:$B$11,MATCH($D16,Settings!$A$4:$A$11,0))+INDEX(Settings!$D$4:$D$11,MATCH($D16,Settings!$A$4:$A$11,0)))+INDEX(Settings!$C$4:$C$11,MATCH($D16,Settings!$A$4:$A$11,0))),0)) | K16: =IF($B16="","",IFERROR(INDEX(Inventory!$J$4:$J$503,MATCH($B16,Inventory!$A$4:$A$503,0)),0)) | L16: =IF(OR(B16="",E16=""),"",E16+N(F16)-N(G16)-N(H16)-N(J16)-N(K16)) | M16: =IF(OR(L16="",N(K16)=0),"",L16/K16) | N16: =IF(OR(A16="",B16=""),"",IFERROR(A16-INDEX(Inventory!$B$4:$B$503,MATCH($B16,Inventory!$A$4:$A$503,0)),"")) | O16: =IF($B16="","",IFERROR(INDEX(Inventory!$F$4:$F$503,MATCH($B16,Inventory!$A$4:$A$503,0)),"")) | P16: =IF($B16="","",IFERROR(INDEX(Inventory!$C$4:$C$503,MATCH($B16,Inventory!$A$4:$A$503,0)),""))
C17: =IF($B17="","",IFERROR(INDEX(Inventory!$E$4:$E$503,MATCH($B17,Inventory!$A$4:$A$503,0)),"SKU not found")) | H17: =IF(OR(B17="",D17="",E17=""),"",IFERROR(IF(AND(D17="Poshmark",E17<Settings!$B$20),Settings!$B$21,(E17+IF(INDEX(Settings!$E$4:$E$11,MATCH($D17,Settings!$A$4:$A$11,0))="Y",N(F17),0))*(INDEX(Settings!$B$4:$B$11,MATCH($D17,Settings!$A$4:$A$11,0))+INDEX(Settings!$D$4:$D$11,MATCH($D17,Settings!$A$4:$A$11,0)))+INDEX(Settings!$C$4:$C$11,MATCH($D17,Settings!$A$4:$A$11,0))),0)) | K17: =IF($B17="","",IFERROR(INDEX(Inventory!$J$4:$J$503,MATCH($B17,Inventory!$A$4:$A$503,0)),0)) | L17: =IF(OR(B17="",E17=""),"",E17+N(F17)-N(G17)-N(H17)-N(J17)-N(K17)) | M17: =IF(OR(L17="",N(K17)=0),"",L17/K17) | N17: =IF(OR(A17="",B17=""),"",IFERROR(A17-INDEX(Inventory!$B$4:$B$503,MATCH($B17,Inventory!$A$4:$A$503,0)),"")) | O17: =IF($B17="","",IFERROR(INDEX(Inventory!$F$4:$F$503,MATCH($B17,Inventory!$A$4:$A$503,0)),"")) | P17: =IF($B17="","",IFERROR(INDEX(Inventory!$C$4:$C$503,MATCH($B17,Inventory!$A$4:$A$503,0)),""))
C18: =IF($B18="","",IFERROR(INDEX(Inventory!$E$4:$E$503,MATCH($B18,Inventory!$A$4:$A$503,0)),"SKU not found")) | H18: =IF(OR(B18="",D18="",E18=""),"",IFERROR(IF(AND(D18="Poshmark",E18<Settings!$B$20),Settings!$B$21,(E18+IF(INDEX(Settings!$E$4:$E$11,MATCH($D18,Settings!$A$4:$A$11,0))="Y",N(F18),0))*(INDEX(Settings!$B$4:$B$11,MATCH($D18,Settings!$A$4:$A$11,0))+INDEX(Settings!$D$4:$D$11,MATCH($D18,Settings!$A$4:$A$11,0)))+INDEX(Settings!$C$4:$C$11,MATCH($D18,Settings!$A$4:$A$11,0))),0)) | K18: =IF($B18="","",IFERROR(INDEX(Inventory!$J$4:$J$503,MATCH($B18,Inventory!$A$4:$A$503,0)),0)) | L18: =IF(OR(B18="",E18=""),"",E18+N(F18)-N(G18)-N(H18)-N(J18)-N(K18)) | M18: =IF(OR(L18="",N(K18)=0),"",L18/K18) | N18: =IF(OR(A18="",B18=""),"",IFERROR(A18-INDEX(Inventory!$B$4:$B$503,MATCH($B18,Inventory!$A$4:$A$503,0)),"")) | O18: =IF($B18="","",IFERROR(INDEX(Inventory!$F$4:$F$503,MATCH($B18,Inventory!$A$4:$A$503,0)),"")) | P18: =IF($B18="","",IFERROR(INDEX(Inventory!$C$4:$C$503,MATCH($B18,Inventory!$A$4:$A$503,0)),""))
C19: =IF($B19="","",IFERROR(INDEX(Inventory!$E$4:$E$503,MATCH($B19,Inventory!$A$4:$A$503,0)),"SKU not found")) | H19: =IF(OR(B19="",D19="",E19=""),"",IFERROR(IF(AND(D19="Poshmark",E19<Settings!$B$20),Settings!$B$21,(E19+IF(INDEX(Settings!$E$4:$E$11,MATCH($D19,Settings!$A$4:$A$11,0))="Y",N(F19),0))*(INDEX(Settings!$B$4:$B$11,MATCH($D19,Settings!$A$4:$A$11,0))+INDEX(Settings!$D$4:$D$11,MATCH($D19,Settings!$A$4:$A$11,0)))+INDEX(Settings!$C$4:$C$11,MATCH($D19,Settings!$A$4:$A$11,0))),0)) | K19: =IF($B19="","",IFERROR(INDEX(Inventory!$J$4:$J$503,MATCH($B19,Inventory!$A$4:$A$503,0)),0)) | L19: =IF(OR(B19="",E19=""),"",E19+N(F19)-N(G19)-N(H19)-N(J19)-N(K19)) | M19: =IF(OR(L19="",N(K19)=0),"",L19/K19) | N19: =IF(OR(A19="",B19=""),"",IFERROR(A19-INDEX(Inventory!$B$4:$B$503,MATCH($B19,Inventory!$A$4:$A$503,0)),"")) | O19: =IF($B19="","",IFERROR(INDEX(Inventory!$F$4:$F$503,MATCH($B19,Inventory!$A$4:$A$503,0)),"")) | P19: =IF($B19="","",IFERROR(INDEX(Inventory!$C$4:$C$503,MATCH($B19,Inventory!$A$4:$A$503,0)),""))
C20: =IF($B20="","",IFERROR(INDEX(Inventory!$E$4:$E$503,MATCH($B20,Inventory!$A$4:$A$503,0)),"SKU not found")) | H20: =IF(OR(B20="",D20="",E20=""),"",IFERROR(IF(AND(D20="Poshmark",E20<Settings!$B$20),Settings!$B$21,(E20+IF(INDEX(Settings!$E$4:$E$11,MATCH($D20,Settings!$A$4:$A$11,0))="Y",N(F20),0))*(INDEX(Settings!$B$4:$B$11,MATCH($D20,Settings!$A$4:$A$11,0))+INDEX(Settings!$D$4:$D$11,MATCH($D20,Settings!$A$4:$A$11,0)))+INDEX(Settings!$C$4:$C$11,MATCH($D20,Settings!$A$4:$A$11,0))),0)) | K20: =IF($B20="","",IFERROR(INDEX(Inventory!$J$4:$J$503,MATCH($B20,Inventory!$A$4:$A$503,0)),0)) | L20: =IF(OR(B20="",E20=""),"",E20+N(F20)-N(G20)-N(H20)-N(J20)-N(K20)) | M20: =IF(OR(L20="",N(K20)=0),"",L20/K20) | N20: =IF(OR(A20="",B20=""),"",IFERROR(A20-INDEX(Inventory!$B$4:$B$503,MATCH($B20,Inventory!$A$4:$A$503,0)),"")) | O20: =IF($B20="","",IFERROR(INDEX(Inventory!$F$4:$F$503,MATCH($B20,Inventory!$A$4:$A$503,0)),"")) | P20: =IF($B20="","",IFERROR(INDEX(Inventory!$C$4:$C$503,MATCH($B20,Inventory!$A$4:$A$503,0)),""))
... C503: =IF($B503="","",IFERROR(INDEX(Inventory!$E$4:$E$503,MATCH($B503,Inventory!$A$4:$A$503,0)),"SKU not found")) | H503: =IF(OR(B503="",D503="",E503=""),"",IFERROR(IF(AND(D503="Poshmark",E503<Settings!$B$20),Settings!$B$21,(E503+IF(INDEX(Settings!$E$4:$E$11,MATCH($D503,Settings!$A$4:$A$11,0))="Y",N(F503),0))*(INDEX(Settings!$B$4:$B$11,MATCH($D503,Settings!$A$4:$A$11,0))+INDEX(Settings!$D$4:$D$11,MATCH($D503,Settings!$A$4:$A$11,0)))+INDEX(Settings!$C$4:$C$11,MATCH($D503,Settings!$A$4:$A$11,0))),0)) | K503: =IF($B503="","",IFERROR(INDEX(Inventory!$J$4:$J$503,MATCH($B503,Inventory!$A$4:$A$503,0)),0)) | L503: =IF(OR(B503="",E503=""),"",E503+N(F503)-N(G503)-N(H503)-N(J503)-N(K503)) | M503: =IF(OR(L503="",N(K503)=0),"",L503/K503) | N503: =IF(OR(A503="",B503=""),"",IFERROR(A503-INDEX(Inventory!$B$4:$B$503,MATCH($B503,Inventory!$A$4:$A$503,0)),"")) | O503: =IF($B503="","",IFERROR(INDEX(Inventory!$F$4:$F$503,MATCH($B503,Inventory!$A$4:$A$503,0)),"")) | P503: =IF($B503="","",IFERROR(INDEX(Inventory!$C$4:$C$503,MATCH($B503,Inventory!$A$4:$A$503,0)),""))

Sheet Expenses
A1: Expenses
A2: Business costs not tied to one item. For mileage, enter Miles and the deduction is calculated from Settings.
A3: Date | B3: Category | C3: Description | D3: Amount | E3: Miles | F3: Mileage Deduction | G3: Total Deductible
A4: 46027 | B4: Shipping Supplies | C4: Poly mailers 10x13 (100 pk) + tape | D4: 24.99 | F4: =IF(E4="","",E4*Settings!$B$17) | G4: =IF(A4="","",N(D4)+N(F4)) -> 24.99
A5: 46037 | B5: Mileage | C5: Thrift route - 3 stores | E5: 32 | F5: =IF(E5="","",E5*Settings!$B$17) -> 22.4 | G5: =IF(A5="","",N(D5)+N(F5)) -> 22.4
A6: 46054 | B6: Subscriptions | C6: Crosslisting app - monthly | D6: 19.99 | F6: =IF(E6="","",E6*Settings!$B$17) | G6: =IF(A6="","",N(D6)+N(F6)) -> 19.99
A7: 46091 | B7: Supplies | C7: Garment steamer + lint roller | D7: 38.5 | F7: =IF(E7="","",E7*Settings!$B$17) | G7: =IF(A7="","",N(D7)+N(F7)) -> 38.5
F8: =IF(E8="","",E8*Settings!$B$17) | G8: =IF(A8="","",N(D8)+N(F8))
F9: =IF(E9="","",E9*Settings!$B$17) | G9: =IF(A9="","",N(D9)+N(F9))
F10: =IF(E10="","",E10*Settings!$B$17) | G10: =IF(A10="","",N(D10)+N(F10))
F11: =IF(E11="","",E11*Settings!$B$17) | G11: =IF(A11="","",N(D11)+N(F11))
F12: =IF(E12="","",E12*Settings!$B$17) | G12: =IF(A12="","",N(D12)+N(F12))
F13: =IF(E13="","",E13*Settings!$B$17) | G13: =IF(A13="","",N(D13)+N(F13))
F14: =IF(E14="","",E14*Settings!$B$17) | G14: =IF(A14="","",N(D14)+N(F14))
F15: =IF(E15="","",E15*Settings!$B$17) | G15: =IF(A15="","",N(D15)+N(F15))
F16: =IF(E16="","",E16*Settings!$B$17) | G16: =IF(A16="","",N(D16)+N(F16))
F17: =IF(E17="","",E17*Settings!$B$17) | G17: =IF(A17="","",N(D17)+N(F17))
F18: =IF(E18="","",E18*Settings!$B$17) | G18: =IF(A18="","",N(D18)+N(F18))
F19: =IF(E19="","",E19*Settings!$B$17) | G19: =IF(A19="","",N(D19)+N(F19))
... F503: =IF(E503="","",E503*Settings!$B$17) | G503: =IF(A503="","",N(D503)+N(F503))

Sheet Dashboard
A1: Dashboard
A2: ="Tracking year starting "&TEXT(Settings!$B$15,"mmm d, yyyy")&" - updates automatically" -> Tracking year starting Jan 1, 2026 - updates automatically
A4: ="Inventory Value at Cost (Unsold, "&Settings!$B$14&")" -> Inventory Value at Cost (Unsold, $) | C4: Sell-Through Rate | E4: ="Avg Profit per Item ("&Settings!$B$14&")" -> Avg Profit per Item ($) | G4: Avg ROI | I4: Avg Days to Sell
A5: =SUMIFS(Inventory!$J$4:$J$503,Inventory!$K$4:$K$503,"Sourced")+SUMIFS(Inventory!$J$4:$J$503,Inventory!$K$4:$K$503,"Listed")+SUMIFS(Inventory!$J$4:$J$503,Inventory!$K$4:$K$503,"Returned") -> 80.99 | C5: =IFERROR(COUNTIF(Inventory!$K$4:$K$503,"Sold")/COUNTIF(Inventory!$K$4:$K$503,"?*"),0) -> 0.625 | E5: =IFERROR(AVERAGE(Sales!$L$4:$L$503),0) -> 30.2804 | G5: =IFERROR(AVERAGE(Sales!$M$4:$M$503),0) -> 1.9395903 | I5: =IFERROR(AVERAGE(Sales!$N$4:$N$503),0) -> 24.8
A7: Best Platform by Profit | C7: Death Pile Items (stale) | E7: ="Death Pile Cost ("&Settings!$B$14&")" -> Death Pile Cost ($) | G7: Items Sold (year) | I7: ="Net Profit (year, "&Settings!$B$14&")" -> Net Profit (year, $)
A8: =IFERROR(IF(MAX(E28:E35)=0,"-",INDEX(A28:A35,MATCH(MAX(E28:E35),E28:E35,0))),"-") -> eBay | C8: =COUNTIF(Inventory!$Q$4:$Q$503,"STALE") -> 1 | E8: =SUMIFS(Inventory!$J$4:$J$503,Inventory!$Q$4:$Q$503,"STALE") -> 30.99 | G8: =D24 -> 5 | I8: =J24 -> 45.522
A10: Monthly Performance
A11: Month | B11: Items Sourced | C11: COGS Spent | D11: Items Sold | E11: Gross Sales | F11: Fees | G11: Shipping Net (charged - paid) | H11: Item Profit | I11: Overhead Expenses | J11: Net Profit | L11: Month Start (helper) | M11: Month End (helper)
A12: =TEXT(L12,"mmm yyyy") -> Jan 2026 | B12: =COUNTIFS(Inventory!$B$4:$B$503,">="&$L12,Inventory!$B$4:$B$503,"<"&$M12) -> 2 | C12: =SUMIFS(Inventory!$J$4:$J$503,Inventory!$B$4:$B$503,">="&$L12,Inventory!$B$4:$B$503,"<"&$M12) -> 33.49 | D12: =COUNTIFS(Sales!$A$4:$A$503,">="&$L12,Sales!$A$4:$A$503,"<"&$M12) -> 1 | E12: =SUMIFS(Sales!$E$4:$E$503,Sales!$A$4:$A$503,">="&$L12,Sales!$A$4:$A$503,"<"&$M12) -> 79 | F12: =SUMIFS(Sales!$H$4:$H$503,Sales!$A$4:$A$503,">="&$L12,Sales!$A$4:$A$503,"<"&$M12) -> 11.144 | G12: =SUMIFS(Sales!$F$4:$F$503,Sales!$A$4:$A$503,">="&$L12,Sales!$A$4:$A$503,"<"&$M12)-SUMIFS(Sales!$G$4:$G$503,Sales!$A$4:$A$503,">="&$L12,Sales!$A$4:$A$503,"<"&$M12) -> -9.85 | H12: =SUMIFS(Sales!$L$4:$L$503,Sales!$A$4:$A$503,">="&$L12,Sales!$A$4:$A$503,"<"&$M12) -> 45.016 | I12: =SUMIFS(Expenses!$G$4:$G$503,Expenses!$A$4:$A$503,">="&$L12,Expenses!$A$4:$A$503,"<"&$M12) -> 47.39 | J12: =H12-I12 -> -2.374 | L12: =DATE(YEAR(Settings!$B$15),MONTH(Settings!$B$15)+0,1) -> 46023 | M12: =DATE(YEAR(Settings!$B$15),MONTH(Settings!$B$15)+1,1) -> 46054
A13: =TEXT(L13,"mmm yyyy") -> Feb 2026 | B13: =COUNTIFS(Inventory!$B$4:$B$503,">="&$L13,Inventory!$B$4:$B$503,"<"&$M13) -> 2 | C13: =SUMIFS(Inventory!$J$4:$J$503,Inventory!$B$4:$B$503,">="&$L13,Inventory!$B$4:$B$503,"<"&$M13) -> 29 | D13: =COUNTIFS(Sales!$A$4:$A$503,">="&$L13,Sales!$A$4:$A$503,"<"&$M13) -> 2 | E13: =SUMIFS(Sales!$E$4:$E$503,Sales!$A$4:$A$503,">="&$L13,Sales!$A$4:$A$503,"<"&$M13) -> 133 | F13: =SUMIFS(Sales!$H$4:$H$503,Sales!$A$4:$A$503,">="&$L13,Sales!$A$4:$A$503,"<"&$M13) -> 21.399 | G13: =SUMIFS(Sales!$F$4:$F$503,Sales!$A$4:$A$503,">="&$L13,Sales!$A$4:$A$503,"<"&$M13)-SUMIFS(Sales!$G$4:$G$503,Sales!$A$4:$A$503,">="&$L13,Sales!$A$4:$A$503,"<"&$M13) -> -1.21 | H13: =SUMIFS(Sales!$L$4:$L$503,Sales!$A$4:$A$503,">="&$L13,Sales!$A$4:$A$503,"<"&$M13) -> 62.391 | I13: =SUMIFS(Expenses!$G$4:$G$503,Expenses!$A$4:$A$503,">="&$L13,Expenses!$A$4:$A$503,"<"&$M13) -> 19.99 | J13: =H13-I13 -> 42.401 | L13: =DATE(YEAR(Settings!$B$15),MONTH(Settings!$B$15)+1,1) -> 46054 | M13: =DATE(YEAR(Settings!$B$15),MONTH(Settings!$B$15)+2,1) -> 46082
A14: =TEXT(L14,"mmm yyyy") -> Mar 2026 | B14: =COUNTIFS(Inventory!$B$4:$B$503,">="&$L14,Inventory!$B$4:$B$503,"<"&$M14) -> 2 | C14: =SUMIFS(Inventory!$J$4:$J$503,Inventory!$B$4:$B$503,">="&$L14,Inventory!$B$4:$B$503,"<"&$M14) -> 75.99 | D14: =COUNTIFS(Sales!$A$4:$A$503,">="&$L14,Sales!$A$4:$A$503,"<"&$M14) -> 1 | E14: =SUMIFS(Sales!$E$4:$E$503,Sales!$A$4:$A$503,">="&$L14,Sales!$A$4:$A$503,"<"&$M14) -> 14 | F14: =SUMIFS(Sales!$H$4:$H$503,Sales!$A$4:$A$503,">="&$L14,Sales!$A$4:$A$503,"<"&$M14) -> 2.95 | G14: =SUMIFS(Sales!$F$4:$F$503,Sales!$A$4:$A$503,">="&$L14,Sales!$A$4:$A$503,"<"&$M14)-SUMIFS(Sales!$G$4:$G$503,Sales!$A$4:$A$503,">="&$L14,Sales!$A$4:$A$503,"<"&$M14) -> 0 | H14: =SUMIFS(Sales!$L$4:$L$503,Sales!$A$4:$A$503,">="&$L14,Sales!$A$4:$A$503,"<"&$M14) -> 8.05 | I14: =SUMIFS(Expenses!$G$4:$G$503,Expenses!$A$4:$A$503,">="&$L14,Expenses!$A$4:$A$503,"<"&$M14) -> 38.5 | J14: =H14-I14 -> -30.45 | L14: =DATE(YEAR(Settings!$B$15),MONTH(Settings!$B$15)+2,1) -> 46082 | M14: =DATE(YEAR(Settings!$B$15),MONTH(Settings!$B$15)+3,1) -> 46113
A15: =TEXT(L15,"mmm yyyy") -> Apr 2026 | B15: =COUNTIFS(Inventory!$B$4:$B$503,">="&$L15,Inventory!$B$4:$B$503,"<"&$M15) -> 0 | C15: =SUMIFS(Inventory!$J$4:$J$503,Inventory!$B$4:$B$503,">="&$L15,Inventory!$B$4:$B$503,"<"&$M15) -> 0 | D15: =COUNTIFS(Sales!$A$4:$A$503,">="&$L15,Sales!$A$4:$A$503,"<"&$M15) -> 1 | E15: =SUMIFS(Sales!$E$4:$E$503,Sales!$A$4:$A$503,">="&$L15,Sales!$A$4:$A$503,"<"&$M15) -> 95 | F15: =SUMIFS(Sales!$H$4:$H$503,Sales!$A$4:$A$503,">="&$L15,Sales!$A$4:$A$503,"<"&$M15) -> 10.655 | G15: =SUMIFS(Sales!$F$4:$F$503,Sales!$A$4:$A$503,">="&$L15,Sales!$A$4:$A$503,"<"&$M15)-SUMIFS(Sales!$G$4:$G$503,Sales!$A$4:$A$503,">="&$L15,Sales!$A$4:$A$503,"<"&$M15) -> -3.4 | H15: =SUMIFS(Sales!$L$4:$L$503,Sales!$A$4:$A$503,">="&$L15,Sales!$A$4:$A$503,"<"&$M15) -> 35.945 | I15: =SUMIFS(Expenses!$G$4:$G$503,Expenses!$A$4:$A$503,">="&$L15,Expenses!$A$4:$A$503,"<"&$M15) -> 0 | J15: =H15-I15 -> 35.945 | L15: =DATE(YEAR(Settings!$B$15),MONTH(Settings!$B$15)+3,1) -> 46113 | M15: =DATE(YEAR(Settings!$B$15),MONTH(Settings!$B$15)+4,1) -> 46143
A16: =TEXT(L16,"mmm yyyy") -> May 2026 | B16: =COUNTIFS(Inventory!$B$4:$B$503,">="&$L16,Inventory!$B$4:$B$503,"<"&$M16) -> 0 | C16: =SUMIFS(Inventory!$J$4:$J$503,Inventory!$B$4:$B$503,">="&$L16,Inventory!$B$4:$B$503,"<"&$M16) -> 0 | D16: =COUNTIFS(Sales!$A$4:$A$503,">="&$L16,Sales!$A$4:$A$503,"<"&$M16) -> 0 | E16: =SUMIFS(Sales!$E$4:$E$503,Sales!$A$4:$A$503,">="&$L16,Sales!$A$4:$A$503,"<"&$M16) -> 0 | F16: =SUMIFS(Sales!$H$4:$H$503,Sales!$A$4:$A$503,">="&$L16,Sales!$A$4:$A$503,"<"&$M16) -> 0 | G16: =SUMIFS(Sales!$F$4:$F$503,Sales!$A$4:$A$503,">="&$L16,Sales!$A$4:$A$503,"<"&$M16)-SUMIFS(Sales!$G$4:$G$503,Sales!$A$4:$A$503,">="&$L16,Sales!$A$4:$A$503,"<"&$M16) -> 0 | H16: =SUMIFS(Sales!$L$4:$L$503,Sales!$A$4:$A$503,">="&$L16,Sales!$A$4:$A$503,"<"&$M16) -> 0 | I16: =SUMIFS(Expenses!$G$4:$G$503,Expenses!$A$4:$A$503,">="&$L16,Expenses!$A$4:$A$503,"<"&$M16) -> 0 | J16: =H16-I16 -> 0 | L16: =DATE(YEAR(Settings!$B$15),MONTH(Settings!$B$15)+4,1) -> 46143 | M16: =DATE(YEAR(Settings!$B$15),MONTH(Settings!$B$15)+5,1) -> 46174
A17: =TEXT(L17,"mmm yyyy") -> Jun 2026 | B17: =COUNTIFS(Inventory!$B$4:$B$503,">="&$L17,Inventory!$B$4:$B$503,"<"&$M17) -> 1 | C17: =SUMIFS(Inventory!$J$4:$J$503,Inventory!$B$4:$B$503,">="&$L17,Inventory!$B$4:$B$503,"<"&$M17) -> 30 | D17: =COUNTIFS(Sales!$A$4:$A$503,">="&$L17,Sales!$A$4:$A$503,"<"&$M17) -> 0 | E17: =SUMIFS(Sales!$E$4:$E$503,Sales!$A$4:$A$503,">="&$L17,Sales!$A$4:$A$503,"<"&$M17) -> 0 | F17: =SUMIFS(Sales!$H$4:$H$503,Sales!$A$4:$A$503,">="&$L17,Sales!$A$4:$A$503,"<"&$M17) -> 0 | G17: =SUMIFS(Sales!$F$4:$F$503,Sales!$A$4:$A$503,">="&$L17,Sales!$A$4:$A$503,"<"&$M17)-SUMIFS(Sales!$G$4:$G$503,Sales!$A$4:$A$503,">="&$L17,Sales!$A$4:$A$503,"<"&$M17) -> 0 | H17: =SUMIFS(Sales!$L$4:$L$503,Sales!$A$4:$A$503,">="&$L17,Sales!$A$4:$A$503,"<"&$M17) -> 0 | I17: =SUMIFS(Expenses!$G$4:$G$503,Expenses!$A$4:$A$503,">="&$L17,Expenses!$A$4:$A$503,"<"&$M17) -> 0 | J17: =H17-I17 -> 0 | L17: =DATE(YEAR(Settings!$B$15),MONTH(Settings!$B$15)+5,1) -> 46174 | M17: =DATE(YEAR(Settings!$B$15),MONTH(Settings!$B$15)+6,1) -> 46204
A18: =TEXT(L18,"mmm yyyy") -> Jul 2026 | B18: =COUNTIFS(Inventory!$B$4:$B$503,">="&$L18,Inventory!$B$4:$B$503,"<"&$M18) -> 0 | C18: =SUMIFS(Inventory!$J$4:$J$503,Inventory!$B$4:$B$503,">="&$L18,Inventory!$B$4:$B$503,"<"&$M18) -> 0 | D18: =COUNTIFS(Sales!$A$4:$A$503,">="&$L18,Sales!$A$4:$A$503,"<"&$M18) -> 0 | E18: =SUMIFS(Sales!$E$4:$E$503,Sales!$A$4:$A$503,">="&$L18,Sales!$A$4:$A$503,"<"&$M18) -> 0 | F18: =SUMIFS(Sales!$H$4:$H$503,Sales!$A$4:$A$503,">="&$L18,Sales!$A$4:$A$503,"<"&$M18) -> 0 | G18: =SUMIFS(Sales!$F$4:$F$503,Sales!$A$4:$A$503,">="&$L18,Sales!$A$4:$A$503,"<"&$M18)-SUMIFS(Sales!$G$4:$G$503,Sales!$A$4:$A$503,">="&$L18,Sales!$A$4:$A$503,"<"&$M18) -> 0 | H18: =SUMIFS(Sales!$L$4:$L$503,Sales!$A$4:$A$503,">="&$L18,Sales!$A$4:$A$503,"<"&$M18) -> 0 | I18: =SUMIFS(Expenses!$G$4:$G$503,Expenses!$A$4:$A$503,">="&$L18,Expenses!$A$4:$A$503,"<"&$M18) -> 0 | J18: =H18-I18 -> 0 | L18: =DATE(YEAR(Settings!$B$15),MONTH(Settings!$B$15)+6,1) -> 46204 | M18: =DATE(YEAR(Settings!$B$15),MONTH(Settings!$B$15)+7,1) -> 46235
A19: =TEXT(L19,"mmm yyyy") -> Aug 2026 | B19: =COUNTIFS(Inventory!$B$4:$B$503,">="&$L19,Inventory!$B$4:$B$503,"<"&$M19) -> 1 | C19: =SUMIFS(Inventory!$J$4:$J$503,Inventory!$B$4:$B$503,">="&$L19,Inventory!$B$4:$B$503,"<"&$M19) -> 20 | D19: =COUNTIFS(Sales!$A$4:$A$503,">="&$L19,Sales!$A$4:$A$503,"<"&$M19) -> 0 | E19: =SUMIFS(Sales!$E$4:$E$503,Sales!$A$4:$A$503,">="&$L19,Sales!$A$4:$A$503,"<"&$M19) -> 0 | F19: =SUMIFS(Sales!$H$4:$H$503,Sales!$A$4:$A$503,">="&$L19,Sales!$A$4:$A$503,"<"&$M19) -> 0 | G19: =SUMIFS(Sales!$F$4:$F$503,Sales!$A$4:$A$503,">="&$L19,Sales!$A$4:$A$503,"<"&$M19)-SUMIFS(Sales!$G$4:$G$503,Sales!$A$4:$A$503,">="&$L19,Sales!$A$4:$A$503,"<"&$M19) -> 0 | H19: =SUMIFS(Sales!$L$4:$L$503,Sales!$A$4:$A$503,">="&$L19,Sales!$A$4:$A$503,"<"&$M19) -> 0 | I19: =SUMIFS(Expenses!$G$4:$G$503,Expenses!$A$4:$A$503,">="&$L19,Expenses!$A$4:$A$503,"<"&$M19) -> 0 | J19: =H19-I19 -> 0 | L19: =DATE(YEAR(Settings!$B$15),MONTH(Settings!$B$15)+7,1) -> 46235 | M19: =DATE(YEAR(Settings!$B$15),MONTH(Settings!$B$15)+8,1) -> 46266
A20: =TEXT(L20,"mmm yyyy") -> Sep 2026 | B20: =COUNTIFS(Inventory!$B$4:$B$503,">="&$L20,Inventory!$B$4:$B$503,"<"&$M20) -> 0 | C20: =SUMIFS(Inventory!$J$4:$J$503,Inventory!$B$4:$B$503,">="&$L20,Inventory!$B$4:$B$503,"<"&$M20) -> 0 | D20: =COUNTIFS(Sales!$A$4:$A$503,">="&$L20,Sales!$A$4:$A$503,"<"&$M20) -> 0 | E20: =SUMIFS(Sales!$E$4:$E$503,Sales!$A$4:$A$503,">="&$L20,Sales!$A$4:$A$503,"<"&$M20) -> 0 | F20: =SUMIFS(Sales!$H$4:$H$503,Sales!$A$4:$A$503,">="&$L20,Sales!$A$4:$A$503,"<"&$M20) -> 0 | G20: =SUMIFS(Sales!$F$4:$F$503,Sales!$A$4:$A$503,">="&$L20,Sales!$A$4:$A$503,"<"&$M20)-SUMIFS(Sales!$G$4:$G$503,Sales!$A$4:$A$503,">="&$L20,Sales!$A$4:$A$503,"<"&$M20) -> 0 | H20: =SUMIFS(Sales!$L$4:$L$503,Sales!$A$4:$A$503,">="&$L20,Sales!$A$4:$A$503,"<"&$M20) -> 0 | I20: =SUMIFS(Expenses!$G$4:$G$503,Expenses!$A$4:$A$503,">="&$L20,Expenses!$A$4:$A$503,"<"&$M20) -> 0 | J20: =H20-I20 -> 0 | L20: =DATE(YEAR(Settings!$B$15),MONTH(Settings!$B$15)+8,1) -> 46266 | M20: =DATE(YEAR(Settings!$B$15),MONTH(Settings!$B$15)+9,1) -> 46296
A21: =TEXT(L21,"mmm yyyy") -> Oct 2026 | B21: =COUNTIFS(Inventory!$B$4:$B$503,">="&$L21,Inventory!$B$4:$B$503,"<"&$M21) -> 0 | C21: =SUMIFS(Inventory!$J$4:$J$503,Inventory!$B$4:$B$503,">="&$L21,Inventory!$B$4:$B$503,"<"&$M21) -> 0 | D21: =COUNTIFS(Sales!$A$4:$A$503,">="&$L21,Sales!$A$4:$A$503,"<"&$M21) -> 0 | E21: =SUMIFS(Sales!$E$4:$E$503,Sales!$A$4:$A$503,">="&$L21,Sales!$A$4:$A$503,"<"&$M21) -> 0 | F21: =SUMIFS(Sales!$H$4:$H$503,Sales!$A$4:$A$503,">="&$L21,Sales!$A$4:$A$503,"<"&$M21) -> 0 | G21: =SUMIFS(Sales!$F$4:$F$503,Sales!$A$4:$A$503,">="&$L21,Sales!$A$4:$A$503,"<"&$M21)-SUMIFS(Sales!$G$4:$G$503,Sales!$A$4:$A$503,">="&$L21,Sales!$A$4:$A$503,"<"&$M21) -> 0 | H21: =SUMIFS(Sales!$L$4:$L$503,Sales!$A$4:$A$503,">="&$L21,Sales!$A$4:$A$503,"<"&$M21) -> 0 | I21: =SUMIFS(Expenses!$G$4:$G$503,Expenses!$A$4:$A$503,">="&$L21,Expenses!$A$4:$A$503,"<"&$M21) -> 0 | J21: =H21-I21 -> 0 | L21: =DATE(YEAR(Settings!$B$15),MONTH(Settings!$B$15)+9,1) -> 46296 | M21: =DATE(YEAR(Settings!$B$15),MONTH(Settings!$B$15)+10,1) -> 46327
A22: =TEXT(L22,"mmm yyyy") -> Nov 2026 | B22: =COUNTIFS(Inventory!$B$4:$B$503,">="&$L22,Inventory!$B$4:$B$503,"<"&$M22) -> 0 | C22: =SUMIFS(Inventory!$J$4:$J$503,Inventory!$B$4:$B$503,">="&$L22,Inventory!$B$4:$B$503,"<"&$M22) -> 0 | D22: =COUNTIFS(Sales!$A$4:$A$503,">="&$L22,Sales!$A$4:$A$503,"<"&$M22) -> 0 | E22: =SUMIFS(Sales!$E$4:$E$503,Sales!$A$4:$A$503,">="&$L22,Sales!$A$4:$A$503,"<"&$M22) -> 0 | F22: =SUMIFS(Sales!$H$4:$H$503,Sales!$A$4:$A$503,">="&$L22,Sales!$A$4:$A$503,"<"&$M22) -> 0 | G22: =SUMIFS(Sales!$F$4:$F$503,Sales!$A$4:$A$503,">="&$L22,Sales!$A$4:$A$503,"<"&$M22)-SUMIFS(Sales!$G$4:$G$503,Sales!$A$4:$A$503,">="&$L22,Sales!$A$4:$A$503,"<"&$M22) -> 0 | H22: =SUMIFS(Sales!$L$4:$L$503,Sales!$A$4:$A$503,">="&$L22,Sales!$A$4:$A$503,"<"&$M22) -> 0 | I22: =SUMIFS(Expenses!$G$4:$G$503,Expenses!$A$4:$A$503,">="&$L22,Expenses!$A$4:$A$503,"<"&$M22) -> 0 | J22: =H22-I22 -> 0 | L22: =DATE(YEAR(Settings!$B$15),MONTH(Settings!$B$15)+10,1) -> 46327 | M22: =DATE(YEAR(Settings!$B$15),MONTH(Settings!$B$15)+11,1) -> 46357
A23: =TEXT(L23,"mmm yyyy") -> Dec 2026 | B23: =COUNTIFS(Inventory!$B$4:$B$503,">="&$L23,Inventory!$B$4:$B$503,"<"&$M23) -> 0 | C23: =SUMIFS(Inventory!$J$4:$J$503,Inventory!$B$4:$B$503,">="&$L23,Inventory!$B$4:$B$503,"<"&$M23) -> 0 | D23: =COUNTIFS(Sales!$A$4:$A$503,">="&$L23,Sales!$A$4:$A$503,"<"&$M23) -> 0 | E23: =SUMIFS(Sales!$E$4:$E$503,Sales!$A$4:$A$503,">="&$L23,Sales!$A$4:$A$503,"<"&$M23) -> 0 | F23: =SUMIFS(Sales!$H$4:$H$503,Sales!$A$4:$A$503,">="&$L23,Sales!$A$4:$A$503,"<"&$M23) -> 0 | G23: =SUMIFS(Sales!$F$4:$F$503,Sales!$A$4:$A$503,">="&$L23,Sales!$A$4:$A$503,"<"&$M23)-SUMIFS(Sales!$G$4:$G$503,Sales!$A$4:$A$503,">="&$L23,Sales!$A$4:$A$503,"<"&$M23) -> 0 | H23: =SUMIFS(Sales!$L$4:$L$503,Sales!$A$4:$A$503,">="&$L23,Sales!$A$4:$A$503,"<"&$M23) -> 0 | I23: =SUMIFS(Expenses!$G$4:$G$503,Expenses!$A$4:$A$503,">="&$L23,Expenses!$A$4:$A$503,"<"&$M23) -> 0 | J23: =H23-I23 -> 0 | L23: =DATE(YEAR(Settings!$B$15),MONTH(Settings!$B$15)+11,1) -> 46357 | M23: =DATE(YEAR(Settings!$B$15),MONTH(Settings!$B$15)+12,1) -> 46388
A24: TOTAL | B24: =SUM(B12:B23) -> 8 | C24: =SUM(C12:C23) -> 188.48 | D24: =SUM(D12:D23) -> 5 | E24: =SUM(E12:E23) -> 321 | F24: =SUM(F12:F23) -> 46.148 | G24: =SUM(G12:G23) -> -14.46 | H24: =SUM(H12:H23) -> 151.402 | I24: =SUM(I12:I23) -> 105.88 | J24: =SUM(J12:J23) -> 45.522
A26: Performance by Platform
A27: Platform | B27: Items Sold | C27: Gross Sales | D27: Fees | E27: Net Profit | F27: Avg Profit / Item | G27: Avg ROI
A28: =Settings!A4 -> eBay | B28: =COUNTIFS(Sales!$D$4:$D$503,$A28,Sales!$E$4:$E$503,"<>") -> 1 | C28: =SUMIFS(Sales!$E$4:$E$503,Sales!$D$4:$D$503,$A28) -> 79 | D28: =SUMIFS(Sales!$H$4:$H$503,Sales!$D$4:$D$503,$A28) -> 11.144 | E28: =SUMIFS(Sales!$L$4:$L$503,Sales!$D$4:$D$503,$A28) -> 45.016 | F28: =IF(B28=0,0,E28/B28) -> 45.016 | G28: =IFERROR(E28/SUMIFS(Sales!$K$4:$K$503,Sales!$D$4:$D$503,$A28),0) -> 3.4654349
A29: =Settings!A5 -> Poshmark | B29: =COUNTIFS(Sales!$D$4:$D$503,$A29,Sales!$E$4:$E$503,"<>") -> 2 | C29: =SUMIFS(Sales!$E$4:$E$503,Sales!$D$4:$D$503,$A29) -> 82 | D29: =SUMIFS(Sales!$H$4:$H$503,Sales!$D$4:$D$503,$A29) -> 16.55 | E29: =SUMIFS(Sales!$L$4:$L$503,Sales!$D$4:$D$503,$A29) -> 36.45 | F29: =IF(B29=0,0,E29/B29) -> 18.225 | G29: =IFERROR(E29/SUMIFS(Sales!$K$4:$K$503,Sales!$D$4:$D$503,$A29),0) -> 1.2568966
A30: =Settings!A6 -> Mercari | B30: =COUNTIFS(Sales!$D$4:$D$503,$A30,Sales!$E$4:$E$503,"<>") -> 1 | C30: =SUMIFS(Sales!$E$4:$E$503,Sales!$D$4:$D$503,$A30) -> 65 | D30: =SUMIFS(Sales!$H$4:$H$503,Sales!$D$4:$D$503,$A30) -> 7.799 | E30: =SUMIFS(Sales!$L$4:$L$503,Sales!$D$4:$D$503,$A30) -> 33.991 | F30: =IF(B30=0,0,E30/B30) -> 33.991 | G30: =IFERROR(E30/SUMIFS(Sales!$K$4:$K$503,Sales!$D$4:$D$503,$A30),0) -> 1.6580976
A31: =Settings!A7 -> Depop | B31: =COUNTIFS(Sales!$D$4:$D$503,$A31,Sales!$E$4:$E$503,"<>") -> 0 | C31: =SUMIFS(Sales!$E$4:$E$503,Sales!$D$4:$D$503,$A31) -> 0 | D31: =SUMIFS(Sales!$H$4:$H$503,Sales!$D$4:$D$503,$A31) -> 0 | E31: =SUMIFS(Sales!$L$4:$L$503,Sales!$D$4:$D$503,$A31) -> 0 | F31: =IF(B31=0,0,E31/B31) -> 0 | G31: =IFERROR(E31/SUMIFS(Sales!$K$4:$K$503,Sales!$D$4:$D$503,$A31),0) -> 0
A32: =Settings!A8 -> Whatnot | B32: =COUNTIFS(Sales!$D$4:$D$503,$A32,Sales!$E$4:$E$503,"<>") -> 1 | C32: =SUMIFS(Sales!$E$4:$E$503,Sales!$D$4:$D$503,$A32) -> 95 | D32: =SUMIFS(Sales!$H$4:$H$503,Sales!$D$4:$D$503,$A32) -> 10.655 | E32: =SUMIFS(Sales!$L$4:$L$503,Sales!$D$4:$D$503,$A32) -> 35.945 | F32: =IF(B32=0,0,E32/B32) -> 35.945 | G32: =IFERROR(E32/SUMIFS(Sales!$K$4:$K$503,Sales!$D$4:$D$503,$A32),0) -> 0.79877778
A33: =Settings!A9 -> FB Marketplace | B33: =COUNTIFS(Sales!$D$4:$D$503,$A33,Sales!$E$4:$E$503,"<>") -> 0 | C33: =SUMIFS(Sales!$E$4:$E$503,Sales!$D$4:$D$503,$A33) -> 0 | D33: =SUMIFS(Sales!$H$4:$H$503,Sales!$D$4:$D$503,$A33) -> 0 | E33: =SUMIFS(Sales!$L$4:$L$503,Sales!$D$4:$D$503,$A33) -> 0 | F33: =IF(B33=0,0,E33/B33) -> 0 | G33: =IFERROR(E33/SUMIFS(Sales!$K$4:$K$503,Sales!$D$4:$D$503,$A33),0) -> 0
A34: =Settings!A10 -> Etsy | B34: =COUNTIFS(Sales!$D$4:$D$503,$A34,Sales!$E$4:$E$503,"<>") -> 0 | C34: =SUMIFS(Sales!$E$4:$E$503,Sales!$D$4:$D$503,$A34) -> 0 | D34: =SUMIFS(Sales!$H$4:$H$503,Sales!$D$4:$D$503,$A34) -> 0 | E34: =SUMIFS(Sales!$L$4:$L$503,Sales!$D$4:$D$503,$A34) -> 0 | F34: =IF(B34=0,0,E34/B34) -> 0 | G34: =IFERROR(E34/SUMIFS(Sales!$K$4:$K$503,Sales!$D$4:$D$503,$A34),0) -> 0
A35: =Settings!A11 -> Other | B35: =COUNTIFS(Sales!$D$4:$D$503,$A35,Sales!$E$4:$E$503,"<>") -> 0 | C35: =SUMIFS(Sales!$E$4:$E$503,Sales!$D$4:$D$503,$A35) -> 0 | D35: =SUMIFS(Sales!$H$4:$H$503,Sales!$D$4:$D$503,$A35) -> 0 | E35: =SUMIFS(Sales!$L$4:$L$503,Sales!$D$4:$D$503,$A35) -> 0 | F35: =IF(B35=0,0,E35/B35) -> 0 | G35: =IFERROR(E35/SUMIFS(Sales!$K$4:$K$503,Sales!$D$4:$D$503,$A35),0) -> 0
A37: Performance by Category
A38: Category | B38: Items Sourced | C38: Items Sold | D38: Cost Invested (all) | E38: Unsold at Cost | F38: Net Profit (sold) | G38: ROI (sold)
A39: =Settings!I4 -> Clothing | B39: =COUNTIFS(Inventory!$F$4:$F$503,$A39,Inventory!$B$4:$B$503,"<>") -> 4 | C39: =COUNTIFS(Sales!$O$4:$O$503,$A39,Sales!$E$4:$E$503,"<>") -> 2 | D39: =SUMIFS(Inventory!$J$4:$J$503,Inventory!$F$4:$F$503,$A39) -> 66.98 | E39: =D39-SUMIFS(Inventory!$J$4:$J$503,Inventory!$F$4:$F$503,$A39,Inventory!$K$4:$K$503,"Sold")-SUMIFS(Inventory!$J$4:$J$503,Inventory!$F$4:$F$503,$A39,Inventory!$K$4:$K$503,"Donated") -> 50.99 | F39: =SUMIFS(Sales!$L$4:$L$503,Sales!$O$4:$O$503,$A39) -> 53.066 | G39: =IFERROR(F39/SUMIFS(Sales!$K$4:$K$503,Sales!$O$4:$O$503,$A39),0) -> 3.3186992
A40: =Settings!I5 -> Shoes | B40: =COUNTIFS(Inventory!$F$4:$F$503,$A40,Inventory!$B$4:$B$503,"<>") -> 1 | C40: =COUNTIFS(Sales!$O$4:$O$503,$A40,Sales!$E$4:$E$503,"<>") -> 1 | D40: =SUMIFS(Inventory!$J$4:$J$503,Inventory!$F$4:$F$503,$A40) -> 26 | E40: =D40-SUMIFS(Inventory!$J$4:$J$503,Inventory!$F$4:$F$503,$A40,Inventory!$K$4:$K$503,"Sold")-SUMIFS(Inventory!$J$4:$J$503,Inventory!$F$4:$F$503,$A40,Inventory!$K$4:$K$503,"Donated") -> 0 | F40: =SUMIFS(Sales!$L$4:$L$503,Sales!$O$4:$O$503,$A40) -> 28.4 | G40: =IFERROR(F40/SUMIFS(Sales!$K$4:$K$503,Sales!$O$4:$O$503,$A40),0) -> 1.0923077
A41: =Settings!I6 -> Accessories | B41: =COUNTIFS(Inventory!$F$4:$F$503,$A41,Inventory!$B$4:$B$503,"<>") -> 0 | C41: =COUNTIFS(Sales!$O$4:$O$503,$A41,Sales!$E$4:$E$503,"<>") -> 0 | D41: =SUMIFS(Inventory!$J$4:$J$503,Inventory!$F$4:$F$503,$A41) -> 0 | E41: =D41-SUMIFS(Inventory!$J$4:$J$503,Inventory!$F$4:$F$503,$A41,Inventory!$K$4:$K$503,"Sold")-SUMIFS(Inventory!$J$4:$J$503,Inventory!$F$4:$F$503,$A41,Inventory!$K$4:$K$503,"Donated") -> 0 | F41: =SUMIFS(Sales!$L$4:$L$503,Sales!$O$4:$O$503,$A41) -> 0 | G41: =IFERROR(F41/SUMIFS(Sales!$K$4:$K$503,Sales!$O$4:$O$503,$A41),0) -> 0
A42: =Settings!I7 -> Electronics | B42: =COUNTIFS(Inventory!$F$4:$F$503,$A42,Inventory!$B$4:$B$503,"<>") -> 1 | C42: =COUNTIFS(Sales!$O$4:$O$503,$A42,Sales!$E$4:$E$503,"<>") -> 0 | D42: =SUMIFS(Inventory!$J$4:$J$503,Inventory!$F$4:$F$503,$A42) -> 30 | E42: =D42-SUMIFS(Inventory!$J$4:$J$503,Inventory!$F$4:$F$503,$A42,Inventory!$K$4:$K$503,"Sold")-SUMIFS(Inventory!$J$4:$J$503,Inventory!$F$4:$F$503,$A42,Inventory!$K$4:$K$503,"Donated") -> 30 | F42: =SUMIFS(Sales!$L$4:$L$503,Sales!$O$4:$O$503,$A42) -> 0 | G42: =IFERROR(F42/SUMIFS(Sales!$K$4:$K$503,Sales!$O$4:$O$503,$A42),0) -> 0
A43: =Settings!I8 -> Home | B43: =COUNTIFS(Inventory!$F$4:$F$503,$A43,Inventory!$B$4:$B$503,"<>") -> 1 | C43: =COUNTIFS(Sales!$O$4:$O$503,$A43,Sales!$E$4:$E$503,"<>") -> 1 | D43: =SUMIFS(Inventory!$J$4:$J$503,Inventory!$F$4:$F$503,$A43) -> 20.5 | E43: =D43-SUMIFS(Inventory!$J$4:$J$503,Inventory!$F$4:$F$503,$A43,Inventory!$K$4:$K$503,"Sold")-SUMIFS(Inventory!$J$4:$J$503,Inventory!$F$4:$F$503,$A43,Inventory!$K$4:$K$503,"Donated") -> 0 | F43: =SUMIFS(Sales!$L$4:$L$503,Sales!$O$4:$O$503,$A43) -> 33.991 | G43: =IFERROR(F43/SUMIFS(Sales!$K$4:$K$503,Sales!$O$4:$O$503,$A43),0) -> 1.6580976
A44: =Settings!I9 -> Toys | B44: =COUNTIFS(Inventory!$F$4:$F$503,$A44,Inventory!$B$4:$B$503,"<>") -> 1 | C44: =COUNTIFS(Sales!$O$4:$O$503,$A44,Sales!$E$4:$E$503,"<>") -> 1 | D44: =SUMIFS(Inventory!$J$4:$J$503,Inventory!$F$4:$F$503,$A44) -> 45 | E44: =D44-SUMIFS(Inventory!$J$4:$J$503,Inventory!$F$4:$F$503,$A44,Inventory!$K$4:$K$503,"Sold")-SUMIFS(Inventory!$J$4:$J$503,Inventory!$F$4:$F$503,$A44,Inventory!$K$4:$K$503,"Donated") -> 0 | F44: =SUMIFS(Sales!$L$4:$L$503,Sales!$O$4:$O$503,$A44) -> 35.945 | G44: =IFERROR(F44/SUMIFS(Sales!$K$4:$K$503,Sales!$O$4:$O$503,$A44),0) -> 0.79877778
A45: =Settings!I10 -> Books & Media | B45: =COUNTIFS(Inventory!$F$4:$F$503,$A45,Inventory!$B$4:$B$503,"<>") -> 0 | C45: =COUNTIFS(Sales!$O$4:$O$503,$A45,Sales!$E$4:$E$503,"<>") -> 0 | D45: =SUMIFS(Inventory!$J$4:$J$503,Inventory!$F$4:$F$503,$A45) -> 0 | E45: =D45-SUMIFS(Inventory!$J$4:$J$503,Inventory!$F$4:$F$503,$A45,Inventory!$K$4:$K$503,"Sold")-SUMIFS(Inventory!$J$4:$J$503,Inventory!$F$4:$F$503,$A45,Inventory!$K$4:$K$503,"Donated") -> 0 | F45: =SUMIFS(Sales!$L$4:$L$503,Sales!$O$4:$O$503,$A45) -> 0 | G45: =IFERROR(F45/SUMIFS(Sales!$K$4:$K$503,Sales!$O$4:$O$503,$A45),0) -> 0
...

Sheet Death Pile
A1: Death Pile - Stale Listings
A2: Items with Status = Listed that have been live longer than the Settings threshold. Automatic - nothing to type here.
A4: Stale threshold (days) | B4: =Settings!$B$19 -> 60
A5: Stale items | B5: =COUNTIF(Inventory!$Q$4:$Q$503,"STALE") -> 1
A6: Cash tied up (at cost) | B6: =SUMIFS(Inventory!$J$4:$J$503,Inventory!$Q$4:$Q$503,"STALE") -> 30.99
A7: Total list value | B7: =SUMIFS(Inventory!$M$4:$M$503,Inventory!$Q$4:$Q$503,"STALE") -> 145
A9: # | B9: SKU | C9: Brand | D9: Item Description | E9: Category | F9: Platform Listed | G9: Date Listed | H9: Days Listed | I9: List Price | J9: Total Cost | K9: 15% Markdown Price
